2025-09-03 10:20:33,705 - ERROR - Erro inesperado ao inserir Responsavel:
	Traceback (most recent call last):
	  File "/home/davi/Downloads/Teste Final/keyControlBack/resources/ResponsavelResource.py", line 38, in post
	    validado = schema.load(dados)
	               ^^^^^^^^^^^^^^^^^^
	  File "/home/davi/Downloads/Teste Final/keyControlBack/venv/lib/python3.12/site-packages/marshmallow/schema.py", line 730, in load
	    return self._do_load(
	           ^^^^^^^^^^^^^^
	  File "/home/davi/Downloads/Teste Final/keyControlBack/venv/lib/python3.12/site-packages/marshmallow/schema.py", line 895, in _do_load
	    self._invoke_field_validators(
	  File "/home/davi/Downloads/Teste Final/keyControlBack/venv/lib/python3.12/site-packages/marshmallow/schema.py", line 1161, in _invoke_field_validators
	    validated_value = self._call_and_store(
	                      ^^^^^^^^^^^^^^^^^^^^^
	  File "/home/davi/Downloads/Teste Final/keyControlBack/venv/lib/python3.12/site-packages/marshmallow/schema.py", line 517, in _call_and_store
	    value = getter_func(data)
	            ^^^^^^^^^^^^^^^^^
	TypeError: ResponsavelSchema.validate_unique_cpf() got an unexpected keyword argument 'data_key'
	
2025-09-03 10:27:41,988 - INFO - POST - Novo Responsavel
2025-09-03 10:27:51,611 - INFO - POST - Novo Responsavel
2025-09-03 10:28:03,632 - INFO - POST - Novo Responsavel
2025-09-03 10:33:32,654 - INFO - POST - Novo Responsavel
2025-09-03 10:35:59,947 - INFO - POST - Novo Responsavel
2025-09-03 10:39:13,462 - INFO - GET ALL - Listagem de Salas
2025-09-03 10:39:13,466 - INFO - Salas retornadas com sucesso
2025-09-03 10:40:22,033 - INFO - GET ALL - Listagem de Salas
2025-09-03 10:40:22,035 - INFO - Salas retornadas com sucesso
2025-09-03 10:40:26,097 - INFO - POST - Nova Sala
2025-09-03 10:40:26,098 - WARNING - Erro de validação: {'sala_nome': ['Length must be between 3 and 255.'], 'chave_nome': ['Length must be between 3 and 255.']}
