2025-09-03 10:06:51,280 - ERROR - Erro SQLAlchemy ao inserir Responsavel:
	Traceback (most recent call last):
	  File "/home/davi/Downloads/Teste Final/keyControlBack/venv/lib/python3.12/site-packages/sqlalchemy/engine/base.py", line 1963, in _exec_single_context
	    self.dialect.do_execute(
	  File "/home/davi/Downloads/Teste Final/keyControlBack/venv/lib/python3.12/site-packages/sqlalchemy/engine/default.py", line 943, in do_execute
	    cursor.execute(statement, parameters)
	psycopg2.errors.UniqueViolation: duplicate key value violates unique constraint "responsavel_responsavel_siap_key"
	DETAIL:  Key (responsavel_siap)=(5555) already exists.
	
	
	The above exception was the direct cause of the following exception:
	
	Traceback (most recent call last):
	  File "/home/davi/Downloads/Teste Final/keyControlBack/resources/ResponsavelResource.py", line 41, in post
	    db.session.commit()
	  File "/home/davi/Downloads/Teste Final/keyControlBack/venv/lib/python3.12/site-packages/sqlalchemy/orm/scoping.py", line 599, in commit
	    return self._proxied.commit()
	           ^^^^^^^^^^^^^^^^^^^^^^
	  File "/home/davi/Downloads/Teste Final/keyControlBack/venv/lib/python3.12/site-packages/sqlalchemy/orm/session.py", line 2032, in commit
	    trans.commit(_to_root=True)
	  File "<string>", line 2, in commit
	  File "/home/davi/Downloads/Teste Final/keyControlBack/venv/lib/python3.12/site-packages/sqlalchemy/orm/state_changes.py", line 139, in _go
	    ret_value = fn(self, *arg, **kw)
	                ^^^^^^^^^^^^^^^^^^^^
	  File "/home/davi/Downloads/Teste Final/keyControlBack/venv/lib/python3.12/site-packages/sqlalchemy/orm/session.py", line 1313, in commit
	    self._prepare_impl()
	  File "<string>", line 2, in _prepare_impl
	  File "/home/davi/Downloads/Teste Final/keyControlBack/venv/lib/python3.12/site-packages/sqlalchemy/orm/state_changes.py", line 139, in _go
	    ret_value = fn(self, *arg, **kw)
	                ^^^^^^^^^^^^^^^^^^^^
	  File "/home/davi/Downloads/Teste Final/keyControlBack/venv/lib/python3.12/site-packages/sqlalchemy/orm/session.py", line 1288, in _prepare_impl
	    self.session.flush()
	  File "/home/davi/Downloads/Teste Final/keyControlBack/venv/lib/python3.12/site-packages/sqlalchemy/orm/session.py", line 4345, in flush
	    self._flush(objects)
	  File "/home/davi/Downloads/Teste Final/keyControlBack/venv/lib/python3.12/site-packages/sqlalchemy/orm/session.py", line 4480, in _flush
	    with util.safe_reraise():
	  File "/home/davi/Downloads/Teste Final/keyControlBack/venv/lib/python3.12/site-packages/sqlalchemy/util/langhelpers.py", line 224, in __exit__
	    raise exc_value.with_traceback(exc_tb)
	  File "/home/davi/Downloads/Teste Final/keyControlBack/venv/lib/python3.12/site-packages/sqlalchemy/orm/session.py", line 4441, in _flush
	    flush_context.execute()
	  File "/home/davi/Downloads/Teste Final/keyControlBack/venv/lib/python3.12/site-packages/sqlalchemy/orm/unitofwork.py", line 466, in execute
	    rec.execute(self)
	  File "/home/davi/Downloads/Teste Final/keyControlBack/venv/lib/python3.12/site-packages/sqlalchemy/orm/unitofwork.py", line 642, in execute
	    util.preloaded.orm_persistence.save_obj(
	  File "/home/davi/Downloads/Teste Final/keyControlBack/venv/lib/python3.12/site-packages/sqlalchemy/orm/persistence.py", line 93, in save_obj
	    _emit_insert_statements(
	  File "/home/davi/Downloads/Teste Final/keyControlBack/venv/lib/python3.12/site-packages/sqlalchemy/orm/persistence.py", line 1233, in _emit_insert_statements
	    result = connection.execute(
	             ^^^^^^^^^^^^^^^^^^^
	  File "/home/davi/Downloads/Teste Final/keyControlBack/venv/lib/python3.12/site-packages/sqlalchemy/engine/base.py", line 1415, in execute
	    return meth(
	           ^^^^^
	  File "/home/davi/Downloads/Teste Final/keyControlBack/venv/lib/python3.12/site-packages/sqlalchemy/sql/elements.py", line 523, in _execute_on_connection
	    return connection._execute_clauseelement(
	           ^^^^^^^^^^^^^^^^^^^^^^^^^^^^^^^^^^
	  File "/home/davi/Downloads/Teste Final/keyControlBack/venv/lib/python3.12/site-packages/sqlalchemy/engine/base.py", line 1637, in _execute_clauseelement
	    ret = self._execute_context(
	          ^^^^^^^^^^^^^^^^^^^^^^
	  File "/home/davi/Downloads/Teste Final/keyControlBack/venv/lib/python3.12/site-packages/sqlalchemy/engine/base.py", line 1842, in _execute_context
	    return self._exec_single_context(
	           ^^^^^^^^^^^^^^^^^^^^^^^^^^
	  File "/home/davi/Downloads/Teste Final/keyControlBack/venv/lib/python3.12/site-packages/sqlalchemy/engine/base.py", line 1982, in _exec_single_context
	    self._handle_dbapi_exception(
	  File "/home/davi/Downloads/Teste Final/keyControlBack/venv/lib/python3.12/site-packages/sqlalchemy/engine/base.py", line 2351, in _handle_dbapi_exception
	    raise sqlalchemy_exception.with_traceback(exc_info[2]) from e
	  File "/home/davi/Downloads/Teste Final/keyControlBack/venv/lib/python3.12/site-packages/sqlalchemy/engine/base.py", line 1963, in _exec_single_context
	    self.dialect.do_execute(
	  File "/home/davi/Downloads/Teste Final/keyControlBack/venv/lib/python3.12/site-packages/sqlalchemy/engine/default.py", line 943, in do_execute
	    cursor.execute(statement, parameters)
	sqlalchemy.exc.IntegrityError: (psycopg2.errors.UniqueViolation) duplicate key value violates unique constraint "responsavel_responsavel_siap_key"
	DETAIL:  Key (responsavel_siap)=(5555) already exists.
	
	[SQL: INSERT INTO responsavel (responsavel_nome, responsavel_siap, responsavel_cpf, responsavel_data_nascimento) VALUES (%(responsavel_nome)s, %(responsavel_siap)s, %(responsavel_cpf)s, %(responsavel_data_nascimento)s) RETURNING responsavel.responsavel_id]
	[parameters: {'responsavel_nome': 'Davi', 'responsavel_siap': '5555', 'responsavel_cpf': '1111', 'responsavel_data_nascimento': datetime.date(1990, 7, 11)}]
	(Background on this error at: https://sqlalche.me/e/20/gkpj)
	
2025-09-03 10:18:38,695 - INFO - POST - Novo Responsavel
2025-09-03 10:18:38,697 - ERROR - Erro inesperado ao inserir Responsavel:
	Traceback (most recent call last):
	  File "/home/davi/Downloads/Teste Final/keyControlBack/resources/ResponsavelResource.py", line 38, in post
	    validado = schema.load(dados)
	               ^^^^^^^^^^^^^^^^^^
	  File "/home/davi/Downloads/Teste Final/keyControlBack/venv/lib/python3.12/site-packages/marshmallow/schema.py", line 730, in load
	    return self._do_load(
	           ^^^^^^^^^^^^^^
	  File "/home/davi/Downloads/Teste Final/keyControlBack/venv/lib/python3.12/site-packages/marshmallow/schema.py", line 895, in _do_load
	    self._invoke_field_validators(
	  File "/home/davi/Downloads/Teste Final/keyControlBack/venv/lib/python3.12/site-packages/marshmallow/schema.py", line 1161, in _invoke_field_validators
	    validated_value = self._call_and_store(
	                      ^^^^^^^^^^^^^^^^^^^^^
	  File "/home/davi/Downloads/Teste Final/keyControlBack/venv/lib/python3.12/site-packages/marshmallow/schema.py", line 517, in _call_and_store
	    value = getter_func(data)
	            ^^^^^^^^^^^^^^^^^
	TypeError: ResponsavelSchema.validate_unique_cpf() got an unexpected keyword argument 'data_key'
	
2025-09-03 10:18:44,375 - INFO - POST - Novo Responsavel
2025-09-03 10:18:44,378 - ERROR - Erro inesperado ao inserir Responsavel:
	Traceback (most recent call last):
	  File "/home/davi/Downloads/Teste Final/keyControlBack/resources/ResponsavelResource.py", line 38, in post
	    validado = schema.load(dados)
	               ^^^^^^^^^^^^^^^^^^
	  File "/home/davi/Downloads/Teste Final/keyControlBack/venv/lib/python3.12/site-packages/marshmallow/schema.py", line 730, in load
	    return self._do_load(
	           ^^^^^^^^^^^^^^
	  File "/home/davi/Downloads/Teste Final/keyControlBack/venv/lib/python3.12/site-packages/marshmallow/schema.py", line 895, in _do_load
	    self._invoke_field_validators(
	  File "/home/davi/Downloads/Teste Final/keyControlBack/venv/lib/python3.12/site-packages/marshmallow/schema.py", line 1161, in _invoke_field_validators
	    validated_value = self._call_and_store(
	                      ^^^^^^^^^^^^^^^^^^^^^
	  File "/home/davi/Downloads/Teste Final/keyControlBack/venv/lib/python3.12/site-packages/marshmallow/schema.py", line 517, in _call_and_store
	    value = getter_func(data)
	            ^^^^^^^^^^^^^^^^^
	TypeError: ResponsavelSchema.validate_unique_cpf() got an unexpected keyword argument 'data_key'
	
2025-09-03 10:19:05,005 - INFO - POST - Novo Responsavel
2025-09-03 10:19:05,007 - ERROR - Erro inesperado ao inserir Responsavel:
	Traceback (most recent call last):
	  File "/home/davi/Downloads/Teste Final/keyControlBack/resources/ResponsavelResource.py", line 38, in post
	    validado = schema.load(dados)
	               ^^^^^^^^^^^^^^^^^^
	  File "/home/davi/Downloads/Teste Final/keyControlBack/venv/lib/python3.12/site-packages/marshmallow/schema.py", line 730, in load
	    return self._do_load(
	           ^^^^^^^^^^^^^^
	  File "/home/davi/Downloads/Teste Final/keyControlBack/venv/lib/python3.12/site-packages/marshmallow/schema.py", line 895, in _do_load
	    self._invoke_field_validators(
	  File "/home/davi/Downloads/Teste Final/keyControlBack/venv/lib/python3.12/site-packages/marshmallow/schema.py", line 1161, in _invoke_field_validators
	    validated_value = self._call_and_store(
	                      ^^^^^^^^^^^^^^^^^^^^^
	  File "/home/davi/Downloads/Teste Final/keyControlBack/venv/lib/python3.12/site-packages/marshmallow/schema.py", line 517, in _call_and_store
	    value = getter_func(data)
	            ^^^^^^^^^^^^^^^^^
	TypeError: ResponsavelSchema.validate_unique_cpf() got an unexpected keyword argument 'data_key'
	
2025-09-03 10:20:33,703 - INFO - POST - Novo Responsavel
